Workbook

Sheet Ответы на форму (1)
A1: Отметка времени | B1: В какую возрастную категорию вы входите? | C1: Какого вы пола? | D1: Из какого вы города? | E1: Есть ли у вас дети? | F1: Как часто вы питаетесь стритфудом? | G1: Какой стритфуд вы предпочитаете больше всего? | H1: Пиццу какого бренда вы предпочитаете? | I1: В какое время вы обычно ходите в заведения стрифуда? | J1: Как вы оцениваете вкус и качество продукции Додо Пиццы | K1: Как вы оцениваете качество доставки ДодоПиццы | L1: Как вы оцениваете цены на продукцию ДодоПиццы? | M1: Как вы оцениваете качество обслуживания клиентов ДодоПиццы в целом? | N1: Как вы оцениваете удобство сайта или приложения для оформления заказа? | O1: Как вы оцениваете программу лояльности ДодоПиццы? | P1: Как часто вы заказываете пиццу в ДодоПицце? | Q1: С какой вероятностью вы бы порекомендовали ДодоПиццу знакомым и родственникам? | R1: Какой ваш ежемесячный доход? | S1: Какую долю ваших ежемесячных расходов составляет посещение кафе и ресторанов?
A2: 45556.921 | B2: <18 лет | C2: Мужчина | D2: Казань | E2: Нет | F2: Часто (раз в неделю) | G2: Пицца | H2: ДодоПицца | I2: Днем (с 12:00 до 18:00) | J2: 4 | K2: 5 | L2: 3 | M2: 5 | N2: 5 | O2: 5 | P2: 3 | Q2: 5 | R2: <50 тыс. | S2: 10 - 20
A3: 45556.939 | B3: 18 - 25 лет | C3: Мужчина | D3: Королёв | E3: Нет | F3: Часто (раз в неделю) | G3: Всё, по настроению | H3: ДодоПицца | I3: Вечером (с 18:00 до 24:00) | J3: 4 | K3: 5 | L3: 4 | M3: 5 | N3: 5 | O3: 4 | P3: 3 | Q3: 4 | R3: <50 тыс. | S3: 10 - 20 %
A4: 45557.905 | B4: 18 - 25 лет | C4: Женщина | D4: Москва | E4: Нет | F4: Часто (раз в неделю) | G4: Бургеры | H4: Папа Джонс | I4: Днем (с 12:00 до 18:00) | J4: 3 | K4: 3 | L4: 4 | M4: 4 | N4: 4 | O4: 4 | P4: 2 | Q4: 2 | R4: <50 тыс. | S4: 20 - 30 %
A5: 45557.906 | B5: 18 - 25 лет | C5: Женщина | D5: Киров | E5: Нет | F5: Иногда (раз в пару недель) | G5: Роллы | H5: ДодоПицца | I5: Вечером (с 18:00 до 24:00) | J5: 5 | K5: 5 | L5: 4 | M5: 5 | N5: 5 | O5: 3 | P5: 2 | Q5: 5 | R5: <50 тыс. | S5: Менее 5%
A6: 45557.906 | B6: 18 - 25 лет | C6: Мужчина | D6: Санкт-Петербург | E6: Нет | F6: Иногда (раз в пару недель) | G6: Все, кроме хот-догов | H6: ДодоПицца | I6: Днем (с 12:00 до 18:00) | J6: 4 | L6: 3 | M6: 5 | N6: 5 | O6: 5 | P6: 3 | Q6: 4 | R6: <50 тыс. | S6: 10 - 20 %
A7: 45557.906 | B7: 18 - 25 лет | C7: Мужчина | D7: Санкт-Петербург | E7: Нет | F7: Часто (раз в неделю) | G7: Шаверма | H7: ДодоПицца | I7: Вечером (с 18:00 до 24:00) | J7: 5 | K7: 5 | L7: 3 | M7: 5 | N7: 5 | O7: 3 | P7: 5 | Q7: 5 | R7: <50 тыс. | S7: 5 - 10 %
A8: 45557.907 | B8: 18 - 25 лет | C8: Мужчина | D8: Москва | E8: Нет | F8: Иногда (раз в пару недель) | G8: Бургеры | H8: ДодоПицца | I8: Вечером (с 18:00 до 24:00) | J8: 4 | K8: 3 | L8: 4 | M8: 5 | N8: 5 | O8: 4 | P8: 3 | Q8: 4 | R8: <50 тыс. | S8: 10 - 20 %
A9: 45557.908 | B9: 18 - 25 лет | C9: Женщина | D9: Иннополис | E9: Нет | F9: Иногда (раз в пару недель) | G9: Пицца | H9: ДодоПицца | I9: Вечером (с 18:00 до 24:00) | J9: 4 | K9: 5 | L9: 2 | M9: 4 | N9: 5 | O9: 4 | P9: 3 | Q9: 4 | R9: <50 тыс. | S9: 5 - 10 %
A10: 45557.91 | B10: 18 - 25 лет | C10: Женщина | D10: Казань | E10: Нет | F10: Иногда (раз в пару недель) | G10: Бургеры | H10: ДодоПицца | I10: Вечером (с 18:00 до 24:00) | J10: 4 | K10: 3 | L10: 4 | M10: 4 | N10: 5 | O10: 4 | P10: 3 | Q10: 3 | R10: <50 тыс. | S10: 5 - 10 %
A11: 45557.912 | B11: <18 лет | C11: Мужчина | D11: Казань | E11: Нет | F11: Иногда (раз в пару недель) | G11: Бургеры | H11: ДодоПицца | I11: Днем (с 12:00 до 18:00) | J11: 4 | K11: 4 | L11: 2 | M11: 5 | N11: 5 | O11: 5 | P11: 5 | Q11: 3 | R11: 50 тыс. - 100 тыс. | S11: 10 - 20 %
A12: 45557.912 | B12: 18 - 25 лет | C12: Мужчина | D12: Москвп | E12: Нет | F12: Часто (раз в неделю) | G12: Роллы | H12: ДодоПицца | I12: Вечером (с 18:00 до 24:00) | J12: 5 | K12: 5 | L12: 5 | M12: 3 | N12: 4 | O12: 4 | P12: 5 | Q12: 4 | R12: <50 тыс. | S12: 5 - 10 %
A13: 45557.912 | B13: 18 - 25 лет | C13: Женщина | D13: Москва | E13: Нет | F13: Иногда (раз в пару недель) | G13: Бургеры | H13: ДодоПицца | I13: Днем (с 12:00 до 18:00) | J13: 4 | K13: 5 | L13: 4 | M13: 5 | N13: 5 | O13: 5 | P13: 4 | Q13: 5 | R13: <50 тыс. | S13: Менее 5%
A14: 45557.913 | B14: 18 - 25 лет | C14: Мужчина | D14: Елабуга | E14: Нет | F14: Иногда (раз в пару недель) | G14: Шаурма | H14: ДодоПицца | I14: Днем (с 12:00 до 18:00) | J14: 4 | K14: 4 | L14: 4 | M14: 4 | N14: 3 | O14: 4 | P14: 3 | Q14: 5 | R14: <50 тыс. | S14: 5 - 10 %
A15: 45557.914 | B15: 18 - 25 лет | C15: Женщина | D15: Зеленодольск | E15: Нет | F15: Очень редко (раз в несколько месяцев) | G15: Шаурма | H15: ДодоПицца | I15: Днем (с 12:00 до 18:00) | J15: 4 | K15: 4 | L15: 4 | M15: 5 | N15: 5 | O15: 4 | P15: 3 | Q15: 4 | R15: <50 тыс. | S15: 5 - 10 %
A16: 45557.915 | B16: 18 - 25 лет | C16: Мужчина | D16: Волгодонск | E16: Нет | F16: Часто (раз в неделю) | G16: Пицца | H16: ДодоПицца | I16: Вечером (с 18:00 до 24:00) | J16: 5 | K16: 5 | L16: 4 | M16: 5 | N16: 5 | O16: 5 | P16: 4 | Q16: 5 | R16: <50 тыс. | S16: 10 - 20 %
A17: 45557.918 | B17: <18 лет | C17: Мужчина | D17: Королёв | E17: Нет | F17: Иногда (раз в пару недель) | G17: Пицца | H17: это всё не пиццы, сходите в PiuPiu или Сладкую Италию (второе в Королёве) | I17: Вечером (с 18:00 до 24:00) | J17: 3 | K17: 4 | L17: 4 | M17: 5 | N17: 5 | O17: 5 | P17: 2 | Q17: 3 | R17: 100 - 250 тыс. | S17: 20 - 30 %
A18: 45557.919 | B18: <18 лет | C18: Мужчина | D18: Казань | E18: Нет | F18: Иногда (раз в пару недель) | G18: Шаурма | H18: ДодоПицца | I18: Днем (с 12:00 до 18:00) | J18: 4 | K18: 3 | L18: 3 | M18: 3 | N18: 4 | O18: 4 | P18: 2 | Q18: 4 | R18: <50 тыс. | S18: 10 - 20 %
A19: 45557.919 | B19: 18 - 25 лет | C19: Женщина | D19: Москва | E19: Нет | F19: Иногда (раз в пару недель) | G19: Бургеры | H19: Domino's Pizza | I19: Вечером (с 18:00 до 24:00) | J19: 4 | K19: 5 | L19: 3 | M19: 4 | N19: 2 | O19: 4 | P19: 2 | Q19: 3 | R19: <50 тыс. | S19: 5 - 10 %
A20: 45557.92 | B20: <18 лет | C20: Женщина | D20: Москва | E20: Нет | F20: Очень редко (раз в несколько месяцев) | G20: Роллы | H20: IL Патио | I20: Вечером (с 18:00 до 24:00) | J20: 3 | K20: 3 | L20: 4 | M20: 4 | N20: 5 | P20: 2 | Q20: 2 | R20: <50 тыс. | S20: 5 - 10 %
A21: 45557.921 | B21: <18 лет | C21: Женщина | D21: Казань | E21: Нет | F21: Иногда (раз в пару недель) | G21: Бургеры | H21: ДодоПицца | I21: Вечером (с 18:00 до 24:00) | J21: 4 | L21: 1 | M21: 4 | N21: 5 | O21: 2 | P21: 1 | Q21: 4 | R21: <50 тыс. | S21: 5 - 10 %
A22: 45557.922 | B22: <18 лет | C22: Женщина | D22: Казань | E22: Нет | F22: Очень редко (раз в несколько месяцев) | G22: Пицца | H22: ДодоПицца | I22: Вечером (с 18:00 до 24:00) | J22: 5 | K22: 5 | L22: 4 | M22: 5 | N22: 5 | O22: 5 | P22: 3 | Q22: 5 | R22: <50 тыс. | S22: 10 - 20 %
A23: 45557.925 | B23: <18 лет | C23: Женщина | D23: Спб | E23: Нет | F23: Иногда (раз в пару недель) | G23: Бургеры | H23: ДодоПицца | I23: Вечером (с 18:00 до 24:00) | J23: 5 | K23: 4 | L23: 3 | M23: 5 | N23: 5 | O23: 3 | P23: 2 | Q23: 3 | R23: <50 тыс. | S23: 5 - 10 %
A24: 45557.925 | B24: 18 - 25 лет | C24: Женщина | D24: Казанььььь | E24: Нет | F24: Иногда (раз в пару недель) | G24: Все | H24: ДодоПицца | I24: Днем (с 12:00 до 18:00) | J24: 4 | K24: 4 | L24: 4 | M24: 3 | N24: 4 | O24: 4 | P24: 3 | Q24: 4 | R24: <50 тыс. | S24: 20 - 30 %
A25: 45557.926 | B25: 18 - 25 лет | C25: Женщина | D25: Сочи | E25: Нет | F25: Иногда (раз в пару недель) | G25: Бургеры | H25: ДодоПицца | I25: Днем (с 12:00 до 18:00) | J25: 3 | K25: 4 | L25: 3 | M25: 4 | N25: 5 | O25: 5 | P25: 2 | Q25: 4 | R25: <50 тыс. | S25: 5 - 10 %
A26: 45557.927 | B26: 18 - 25 лет | C26: Мужчина | D26: АЛАБУГА | E26: Нет | F26: Часто (раз в неделю) | G26: Бургеры | H26: ДодоПицца | I26: Вечером (с 18:00 до 24:00) | J26: 5 | K26: 3 | L26: 1 | M26: 4 | N26: 5 | O26: 5 | P26: 3 | Q26: 5 | R26: <50 тыс. | S26: 10 - 20 %
A27: 45557.929 | B27: <18 лет | C27: Мужчина | D27: Елабуга | E27: Нет | F27: Иногда (раз в пару недель) | G27: Шаурма | H27: ДодоПицца | I27: Вечером (с 18:00 до 24:00) | J27: 5 | K27: 4 | L27: 3 | M27: 5 | N27: 5 | O27: 4 | P27: 3 | Q27: 4 | R27: <50 тыс. | S27: Менее 5%
A28: 45557.929 | B28: 18 - 25 лет | C28: Мужчина | D28: Москва | E28: Нет | F28: Часто (раз в неделю) | G28: Бургеры | H28: ДодоПицца | I28: Вечером (с 18:00 до 24:00) | J28: 4 | K28: 4 | L28: 4 | M28: 4 | N28: 5 | O28: 3 | P28: 3 | Q28: 4 | R28: 50 тыс. - 100 тыс. | S28: 5 - 10 %
A29: 45557.93 | B29: <18 лет | C29: Женщина | D29: Казань | E29: Нет | F29: Часто (раз в неделю) | G29: Хот-доги | H29: ДодоПицца | I29: Вечером (с 18:00 до 24:00) | J29: 5 | K29: 5 | L29: 5 | M29: 5 | N29: 5 | O29: 5 | P29: 5 | Q29: 5 | R29: <50 тыс. | S29: 10 - 20 %
A30: 45557.931 | B30: 18 - 25 лет | C30: Мужчина | D30: Королев | E30: Нет | F30: Иногда (раз в пару недель) | G30: Шаурма | H30: ДодоПицца | I30: Вечером (с 18:00 до 24:00) | J30: 4 | K30: 4 | L30: 3 | M30: 4 | N30: 4 | O30: 5 | P30: 3 | Q30: 4 | R30: <50 тыс. | S30: 10 - 20 %
A31: 45557.933 | B31: 18 - 25 лет | C31: Мужчина | D31: Москва | E31: Нет | F31: Иногда (раз в пару недель) | G31: Шаурма | H31: ДодоПицца | I31: Вечером (с 18:00 до 24:00) | J31: 4 | K31: 5 | L31: 4 | M31: 5 | N31: 5 | O31: 5 | P31: 2 | Q31: 3 | R31: <50 тыс. | S31: Менее 5%
A32: 45557.933 | B32: 18 - 25 лет | C32: Мужчина | D32: королев | E32: Нет | F32: Иногда (раз в пару недель) | G32: Шаурма | H32: Domino's Pizza | I32: Вечером (с 18:00 до 24:00) | J32: 5 | K32: 5 | L32: 5 | M32: 5 | N32: 5 | O32: 5 | P32: 3 | Q32: 5 | R32: <50 тыс. | S32: 10 - 20 %
A33: 45557.934 | E33: Да
A34: 45557.935 | B34: 18 - 25 лет | C34: Женщина | D34: Екатеринбург | E34: Нет | F34: Иногда (раз в пару недель) | G34: Пицца | H34: ДодоПицца | I34: Вечером (с 18:00 до 24:00) | J34: 4 | K34: 4 | L34: 5 | M34: 5 | N34: 4 | O34: 5 | P34: 3 | Q34: 5 | R34: <50 тыс. | S34: Менее 5%
A35: 45557.935 | B35: <18 лет | C35: Женщина | D35: Казань | E35: Нет | F35: Иногда (раз в пару недель) | G35: Роллы | H35: ДодоПицца | I35: Днем (с 12:00 до 18:00) | J35: 4 | K35: 5 | L35: 5 | M35: 3 | N35: 5 | O35: 2 | P35: 2 | Q35: 4 | R35: <50 тыс. | S35: Более 50 %
A36: 45557.936 | B36: 18 - 25 лет | C36: Мужчина | D36: Москва | E36: Нет | F36: Иногда (раз в пару недель) | G36: Шаурма | H36: ДодоПицца | I36: Вечером (с 18:00 до 24:00) | J36: 3 | K36: 5 | L36: 3 | M36: 4 | N36: 5 | O36: 3 | P36: 1 | Q36: 4 | R36: <50 тыс. | S36: 5 - 10 %
A37: 45557.938 | B37: 18 - 25 лет | C37: Мужчина | D37: Красногорск | E37: Нет | F37: Иногда (раз в пару недель) | G37: Бургеры | H37: ДодоПицца | I37: Днем (с 12:00 до 18:00) | J37: 5 | K37: 5 | L37: 4 | M37: 5 | N37: 4 | O37: 5 | P37: 4 | Q37: 4 | R37: <50 тыс. | S37: 10 - 20 %
A38: 45557.939 | B38: 18 - 25 лет | C38: Женщина | D38: Москва | E38: Нет | F38: Иногда (раз в пару недель) | G38: Бургеры | H38: Domino's Pizza | I38: Вечером (с 18:00 до 24:00) | J38: 4 | K38: 4 | L38: 4 | M38: 4 | N38: 4 | O38: 4 | P38: 1 | Q38: 4 | R38: <50 тыс. | S38: 20 - 30 %
A39: 45557.939 | B39: 18 - 25 лет | C39: Мужчина | D39: москва | E39: Нет | F39: Иногда (раз в пару недель) | G39: Бургеры | H39: ДодоПицца | I39: Днем (с 12:00 до 18:00) | J39: 4 | K39: 3 | L39: 4 | M39: 5 | N39: 4 | O39: 4 | P39: 3 | Q39: 4 | R39: <50 тыс. | S39: Более 50 %
A40: 45557.94 | B40: 18 - 25 лет | C40: Мужчина | D40: Киев | E40: Нет | F40: Очень редко (раз в несколько месяцев) | G40: Бургеры | H40: ДодоПицца | I40: Днем (с 12:00 до 18:00) | J40: 5 | K40: 5 | L40: 5 | M40: 5 | O40: 5 | P40: 5 | Q40: 5 | R40: 50 тыс. - 100 тыс. | S40: 30 - 50 %
...

Sheet Подсчеты
A1: Процент мужчин | B1: =COUNTIF('Ответы на форму (1)'!C:C,"Мужчина")/COUNT('Ответы на форму (1)'!A:A) -> 0.51315789 | D1: Питаютс очень редко | E1: =COUNTIF('Ответы на форму (1)'!$F:$F,"Очень редко (раз в несколько месяцев)")/COUNT('Ответы на форму (1)'!A:A) -> 0.125 | G1: Предпочитают пиццу | H1: =COUNTIF('Ответы на форму (1)'!G:G, "Пицца") / COUNT('Ответы на форму (1)'!A:A) -> 0.23684211 | J1: Предпочитают пиццу Додо | K1: =COUNTIF('Ответы на форму (1)'!H:H, "ДодоПицца") / COUNT('Ответы на форму (1)'!A:A) -> 0.71710526 | M1: Средняя вероятность рекомендации | N1: =AVERAGE('Ответы на форму (1)'!Q:Q) -> 3.9178082
D2: Питаются иногда | E2: =COUNTIF('Ответы на форму (1)'!$F:$F,"Иногда (раз в пару недель)")/COUNT('Ответы на форму (1)'!A:A) -> 0.46710526
D3: Питаются чаще 1 раза в неделю | E3: =1-E1-E2 -> 0.40789474 | M3: Доход <50 тыс. | N3: =COUNTIF('Ответы на форму (1)'!R:R,"<50 тыс.")/COUNT('Ответы на форму (1)'!A:A) -> 0.80263158
M5: Доля в кошекльке
N6: =COUNTIF('Ответы на форму (1)'!S:S, "менее 5%")/COUNT('Ответы на форму (1)'!A:A) -> 0.19078947
N7: =COUNTIF('Ответы на форму (1)'!S:S, "5 - 10 %")/COUNT('Ответы на форму (1)'!A:A) -> 0.31578947
N8: =COUNTIF('Ответы на форму (1)'!S:S, "10 - 20 %")/COUNT('Ответы на форму (1)'!A:A) -> 0.23684211
N9: =COUNTIF('Ответы на форму (1)'!S:S, "20 - 30 %")/COUNT('Ответы на форму (1)'!A:A) -> 0.078947368
N10: =COUNTIF('Ответы на форму (1)'!S:S, "Более 50 %")/COUNT('Ответы на форму (1)'!A:A) -> 0.085526316
A11: Средяя оценка по показателям | N11: =COUNTIF('Ответы на форму (1)'!S:S, "30 - 50 %")/COUNT('Ответы на форму (1)'!A:A) -> 0.052631579
A12: Продукция | B12: Доставка | C12: Цены | D12: Обслуживание | E12: Удобство сайта | F12: Прог. лояльности | G12: Частота заказов
A13: =AVERAGE('Ответы на форму (1)'!J:J) -> 4.1 | B13: =AVERAGE('Ответы на форму (1)'!K:K) -> 4.1267606 | C13: =AVERAGE('Ответы на форму (1)'!L:L) -> 3.4933333 | D13: =AVERAGE('Ответы на форму (1)'!M:M) -> 4.3355705 | E13: =AVERAGE('Ответы на форму (1)'!N:N) -> 4.2708333 | F13: =AVERAGE('Ответы на форму (1)'!O:O) -> 3.7708333 | G13: =AVERAGE('Ответы на форму (1)'!P:P) -> 2.781457
M16: NPS
M17: Промоутеры | N17: =COUNTIF( 'Ответы на форму (1)'!Q:Q, "5") -> 48 | O17: =N17/COUNT('Ответы на форму (1)'!Q:Q) -> 0.32876712
M18: Детракторы | N18: =COUNTIF( 'Ответы на форму (1)'!Q:Q, "<4") -> 42 | O18: =N18/COUNT('Ответы на форму (1)'!Q:Q) -> 0.28767123
M19: NPS | N19: =(N17-N18)/COUNT('Ответы на форму (1)'!Q:Q) -> 0.04109589 | O19: =O17-O18 -> 0.04109589
